<?xml version="1.0"?>
<robot name="my_robot">

  <!-- Materials -->
  <material name="yellow"><color rgba="0.90 0.88 0.06 1.0"/></material>
  <material name="black"><color rgba="0.0 0.0 0.0 1.0"/></material>
  <material name="white"><color rgba="1.0 1.0 1.0 1.0"/></material>
  <material name="green"><color rgba="0.37 0.90 0.03 1.0"/></material>
  <material name="blue"><color rgba="0.11 0.84 0.92 1.0"/></material>

  <!-- Base Footprint -->
  <link name="base_footprint"/>

  <!-- Base Link -->
  <link name="base_link">
    <visual>
      <geometry><box size="0.36 0.24 0.12"/></geometry>
      <origin xyz="0 0 0.06" rpy="0 0 0"/>
      <material name="yellow"/>
    </visual>
    <collision>
      <geometry><box size="0.36 0.24 0.12"/></geometry>
      <origin xyz="0 0 0.06" rpy="0 0 0"/>
    </collision>
    <inertial>
      <mass value="3.0"/>
      <origin xyz="0 0 0.06" rpy="0 0 0"/>
      <inertia ixx="0.05" ixy="0" ixz="0" iyy="0.05" iyz="0" izz="0.05"/>
    </inertial>
  </link>

  <!-- Lidar Stand -->
  <link name="lidar_stand">
    <visual>
      <geometry><box size="0.04 0.04 0.10"/></geometry>
      <origin xyz="0 0 0.05" rpy="0 0 0"/>
      <material name="white"/>
    </visual>
    <collision>
      <geometry><box size="0.04 0.04 0.10"/></geometry>
      <origin xyz="0 0 0.05" rpy="0 0 0"/>
    </collision>
    <inertial>
      <mass value="0.1"/>
      <origin xyz="0 0 0.05" rpy="0 0 0"/>
      <inertia ixx="0.001" ixy="0" ixz="0" iyy="0.001" iyz="0" izz="0.001"/>
    </inertial>
  </link>

  <!-- Lidar -->
  <link name="lidar_link">
    <visual>
      <geometry><cylinder radius="0.06" length="0.02"/></geometry>
      <origin xyz="0 0 0.01" rpy="0 0 0"/>
      <material name="green"/>
    </visual>
    <collision>
      <geometry><cylinder radius="0.06" length="0.02"/></geometry>
      <origin xyz="0 0 0.01" rpy="0 0 0"/>
    </collision>
    <inertial>
      <mass value="0.2"/>
      <origin xyz="0 0 0.01" rpy="0 0 0"/>
      <inertia ixx="0.001" ixy="0" ixz="0" iyy="0.001" iyz="0" izz="0.001"/>
    </inertial>
  </link>

  <!-- Left Wheel -->
  <link name="left_wheel">
    <visual>
      <geometry><cylinder radius="0.12" length="0.04"/></geometry>
      <origin xyz="0 0 0" rpy="1.57 0 0"/>
      <material name="black"/>
    </visual>
    <collision>
      <geometry><cylinder radius="0.12" length="0.04"/></geometry>
      <origin xyz="0 0 0" rpy="1.57 0 0"/>
    </collision>
    <inertial>
      <mass value="0.5"/>
      <origin xyz="0 0 0" rpy="0 0 0"/>
      <inertia ixx="0.002" ixy="0" ixz="0" iyy="0.002" iyz="0" izz="0.002"/>
    </inertial>
  </link>

  <!-- Right Wheel -->
  <link name="right_wheel">
    <visual>
      <geometry><cylinder radius="0.12" length="0.04"/></geometry>
      <origin xyz="0 0 0" rpy="1.57 0 0"/>
      <material name="black"/>
    </visual>
    <collision>
      <geometry><cylinder radius="0.12" length="0.04"/></geometry>
      <origin xyz="0 0 0" rpy="1.57 0 0"/>
    </collision>
    <inertial>
      <mass value="0.5"/>
      <origin xyz="0 0 0" rpy="0 0 0"/>
      <inertia ixx="0.002" ixy="0" ixz="0" iyy="0.002" iyz="0" izz="0.002"/>
    </inertial>
  </link>

  <!-- IMU -->
  <link name="imu_link">
    <visual>
      <geometry><box size="0.04 0.04 0.02"/></geometry>
      <origin xyz="0 0 0.01" rpy="0 0 0"/>
      <material name="blue"/>
    </visual>
    <collision>
      <geometry><box size="0.04 0.04 0.02"/></geometry>
      <origin xyz="0 0 0.01" rpy="0 0 0"/>
    </collision>
    <inertial>
      <mass value="0.05"/>
      <origin xyz="0 0 0.01" rpy="0 0 0"/>
      <inertia ixx="0.0001" ixy="0" ixz="0" iyy="0.0001" iyz="0" izz="0.0001"/>
    </inertial>
  </link>

  <!-- Caster Base -->
  <link name="caster_base">
    <visual>
      <geometry><cylinder radius="0.06" length="0.06"/></geometry>
      <origin xyz="0 0 0" rpy="0 0 0"/>
      <material name="white"/>
    </visual>
    <collision>
      <geometry><cylinder radius="0.06" length="0.06"/></geometry>
      <origin xyz="0 0 0" rpy="0 0 0"/>
    </collision>
    <inertial>
      <mass value="0.1"/>
      <origin xyz="0 0 0" rpy="0 0 0"/>
      <inertia ixx="0.001" ixy="0" ixz="0" iyy="0.001" iyz="0" izz="0.001"/>
    </inertial>
  </link>

  <!-- Caster Wheel -->
  <link name="caster_wheel">
    <visual>
      <geometry><sphere radius="0.06"/></geometry>
      <origin xyz="0 0 0" rpy="0 0 0"/>
      <material name="white"/>
    </visual>
    <collision>
      <geometry><sphere radius="0.06"/></geometry>
      <origin xyz="0 0 0" rpy="0 0 0"/>
    </collision>
    <inertial>
      <mass value="0.1"/>
      <origin xyz="0 0 0" rpy="0 0 0"/>
      <inertia ixx="0.001" ixy="0" ixz="0" iyy="0.001" iyz="0" izz="0.001"/>
    </inertial>
  </link>

  <!-- Joints -->
  <joint name="base_joint" type="fixed">
    <parent link="base_footprint"/>
    <child link="base_link"/>
    <origin xyz="0 0 0.12" rpy="0 0 0"/>
  </joint>

  <joint name="base_lidar_stand_joint" type="fixed">
    <parent link="base_link"/>
    <child link="lidar_stand"/>
    <origin xyz="-0.09 0 0.17" rpy="0 0 0"/>
  </joint>

  <joint name="lidar_stand_lidar_joint" type="fixed">
    <parent link="lidar_stand"/>
    <child link="lidar_link"/>
    <origin xyz="0 0 0.06" rpy="0 0 0"/>
  </joint>

  <joint name="base_left_wheel_joint" type="continuous">
    <parent link="base_link"/>
    <child link="left_wheel"/>
    <origin xyz="-0.09 0.14 0" rpy="0 0 0"/>
    <axis xyz="0 1 0"/>
  </joint>

  <joint name="base_right_wheel_joint" type="continuous">
    <parent link="base_link"/>
    <child link="right_wheel"/>
    <origin xyz="-0.09 -0.14 0" rpy="0 0 0"/>
    <axis xyz="0 1 0"/>
  </joint>

  <joint name="base_imu_joint" type="fixed">
    <parent link="base_link"/>
    <child link="imu_link"/>
    <origin xyz="0.09 0 0.13" rpy="0 0 0"/>
  </joint>

  <joint name="base_caster_base_joint" type="fixed">
    <parent link="base_link"/>
    <child link="caster_base"/>
    <origin xyz="0.11 0 -0.03" rpy="0 0 0"/>
  </joint>

  <joint name="base_caster_wheel_joint" type="continuous">
    <parent link="caster_base"/>
    <child link="caster_wheel"/>
    <origin xyz="0.0 0 -0.03" rpy="0 0 0"/>
    <axis xyz="0 1 0"/>
  </joint>

  <!-- Diff Drive Plugin -->
    <gazebo>
    <plugin name="diff_drive_controller" filename="libgazebo_ros_diff_drive.so">
        <ros>
        <remapping>cmd_vel:=/cmd_vel</remapping>
        <remapping>odom:=/odom</remapping>
        </ros>
        <left_joint>base_left_wheel_joint</left_joint>
        <right_joint>base_right_wheel_joint</right_joint>
        <wheel_separation>0.28</wheel_separation>
        <wheel_diameter>0.24</wheel_diameter>
        <max_wheel_torque>15</max_wheel_torque>
        <max_wheel_acceleration>0.5</max_wheel_acceleration>
        <command_topic>cmd_vel</command_topic>
        <odometry_frame>odom</odometry_frame>
        <robot_base_frame>base_footprint</robot_base_frame>
        <update_rate>30.0</update_rate>
        <publish_odom>true</publish_odom>
        <publish_odom_tf>true</publish_odom_tf>
    </plugin>
    </gazebo>

    <!-- LiDAR Plugin -->
    <gazebo reference="lidar_link">
    <sensor name="lidar_sensor" type="ray">
        <pose>0 0 0 0 0 0</pose>
        <visualize>true</visualize>
        <update_rate>2</update_rate>
        <ray>
        <scan>
            <horizontal>
            <samples>360</samples>
            <resolution>1</resolution>
            <min_angle>0.000000</min_angle>
            <max_angle>6.280000</max_angle>
            </horizontal>
        </scan>
        <range>
            <min>0.12</min>
            <max>3.5</max>
            <resolution>0.01</resolution>
        </range>
        <noise>
            <type>gaussian</type>
            <mean>0.0</mean>
            <stddev>0.01</stddev>
        </noise>
        </ray>
        <plugin name="scan" filename="libgazebo_ros_ray_sensor.so">
        <ros>
            <remapping>~/out:=/scan</remapping>
        </ros>
        <output_type>sensor_msgs/LaserScan</output_type>
        <frame_name>lidar_link</frame_name>
        </plugin>
    </sensor>
    </gazebo>
    
    <!-- IMU Pligin -->
    <gazebo reference="imu_link">
      <gravity>true</gravity>
      <sensor name="imu_sensor" type="imu">
        <always_on>true</always_on>
        <update_rate>100</update_rate>
        <visualize>true</visualize>
        <topic>__default_topic__</topic>
        <plugin filename="libgazebo_ros_imu_sensor.so" name="imu_plugin">
          <ros>
            <remapping>~/out:=/imu/data</remapping>
          </ros>
          <topicName>imu</topicName>
          <bodyName>imu_link</bodyName>
          <updateRateHZ>10.0</updateRateHZ>
          <gaussianNoise>0.0</gaussianNoise>
          <xyzOffset>0 0 0</xyzOffset>
          <rpyOffset>0 0 0</rpyOffset>
          <frameName>imu_link</frameName>
          <initialOrientationAsReference>false</initialOrientationAsReference>
        </plugin>
        <pose>0 0 0 0 0 0</pose>
      </sensor>
    </gazebo>

    <!-- Joint State -->
    <gazebo>
    <plugin name="joint_state_plugin" filename="libgazebo_ros_joint_state_publisher.so">
        <ros>
        <remapping>~/out:=joint_states</remapping>
        </ros>
        <update_rate>30</update_rate>
        <joint_name>base_left_wheel_joint</joint_name>
        <joint_name>base_right_wheel_joint</joint_name>
    </plugin>
    </gazebo>

</robot>
